Workbook

Sheet Calcutta
A1: Sterling Grove Masters Calcutta
A2: Monte Carlo Fair Value Analysis — April 10, 2026 | G2: 6300
G3: Pot Size
A4: Rank | B4: Team | C4: Player 1 | D4: Player 2 | E4: Team HCP | F4: P(Top 4) | G4: EV @ $6,300 Pot | H4: Auction Price | I4: Owner | K4: Owner Summary
A5: 1 | B5: Team Down The Middle | C5: Mattson (2.3) | D5: Pullen (1.1) | E5: 3.4 | F5: 0.465 | G5: =F5*G$2 -> 2929.5 | H5: 500 | I5: Restivo | K5: Owner | L5: # Teams | M5: Total Paid | N5: Teams Owned
A6: 2 | B6: Pink Lady | C6: Weiss (1.3) | D6: Marino (5.9) | E6: 7.2 | F6: 0.435 | G6: =F6*G$2 -> 2740.5 | H6: 400 | I6: Lewis | K6: Jon | L6: 4 | M6: 1225 | N6: Timex ($425), Foot Wedge ($350), Sand ($250), Beat LA ($200)
A7: 3 | B7: Team DeLaFunk | C7: Funk (4.9) | D7: Laveaga (0.2) | E7: 5.1 | F7: 0.373 | G7: =F7*G$2 -> 2349.9 | H7: 325 | I7: Royce | K7: Restivo | L7: 2 | M7: 800 | N7: Down The Middle ($500), 5 O'Clock Somewhere ($300)
A8: 4 | B8: Team Sticks | C8: Feutz (-1.0) | D8: Adams (-5.4) | E8: -6.4 | F8: 0.337 | G8: =F8*G$2 -> 2123.1 | H8: 500 | I8: Feutz | K8: Lewis | L8: 2 | M8: 800 | N8: Pink Lady ($400), Low Expectations ($400)
A9: 5 | B9: Team Low Expectations | C9: Falagrady (6.7) | D9: Benga (5.3) | E9: 12 | F9: 0.22 | G9: =F9*G$2 -> 1386 | H9: 400 | I9: Lewis | K9: DeLaveaga | L9: 2 | M9: 675 | N9: Winning ($450), Team 20 ($225)
A10: 6 | B10: Team Vanilla Slice | C10: Jerome (9.5) | D10: Ingram (6.8) | E10: 16.3 | F10: 0.205 | G10: =F10*G$2 -> 1291.5 | H10: 300 | I10: Ingram | K10: Royce | L10: 2 | M10: 600 | N10: DeLaFunk ($325), Rough Extractions ($275)
A11: 7 | B11: Team Foot Wedge | C11: Muller (6.9) | D11: Eisenbarth (5.6) | E11: 12.5 | F11: 0.205 | G11: =F11*G$2 -> 1291.5 | H11: 350 | I11: Jon | K11: Feutz | L11: 1 | M11: 500 | N11: Sticks ($500)
A12: 8 | B12: Team Timex | C12: Vrolyks (5.7) | D12: Rucci (11.8) | E12: 17.5 | F12: 0.196 | G12: =F12*G$2 -> 1234.8 | H12: 425 | I12: Jon | K12: Bellows | L12: 2 | M12: 500 | N12: Papa Becko ($375), Index ($125)
A13: 9 | B13: Team Beard | C13: Becko (4.5) | D13: Wasmund (6.0) | E13: 10.5 | F13: 0.181 | G13: =F13*G$2 -> 1140.3 | H13: 275 | I13: Dusty | K13: Jarrett | L13: 2 | M13: 425 | N13: Docks To Docs ($250), Scrabble Rack ($175)
A14: 10 | B14: Team 5 O'Clock Somewhere | C14: Lewis (9.0) | D14: Schueppert (16.8) | E14: 25.8 | F14: 0.173 | G14: =F14*G$2 -> 1089.9 | H14: 300 | I14: Restivo | K14: Ingram | L14: 1 | M14: 300 | N14: Vanilla Slice ($300)
A15: 11 | B15: Team Rough Extractions | C15: Mueller (10.4) | D15: Bellows (7.5) | E15: 17.9 | F15: 0.169 | G15: =F15*G$2 -> 1064.7 | H15: 275 | I15: Royce | K15: Dusty | L15: 1 | M15: 275 | N15: Beard ($275)
A16: 12 | B16: Team Winning | C16: Royce (13.2) | D16: Deuker (2.6) | E16: 15.8 | F16: 0.16 | G16: =F16*G$2 -> 1008 | H16: 450 | I16: DeLaveaga | K16: Bolosan | L16: 1 | M16: 200 | N16: Island Time ($200)
A17: 13 | B17: Papa Becko And The Bomber | C17: Becko (12.0) | D17: Lucas (9.9) | E17: 21.9 | F17: 0.152 | G17: =F17*G$2 -> 957.6 | H17: 375 | I17: Bellows | K17: TOTAL | L17: =SUM(L6:L16) -> 20 | M17: =SUM(M6:M16) -> 6300
A18: 14 | B18: Team Index | C18: Barber (17.0) | D18: Hill (19.6) | E18: 36.6 | F18: 0.136 | G18: =F18*G$2 -> 856.8 | H18: 125 | I18: Bellows
A19: 15 | B19: Patty Ice And The Scrabble Rack | C19: Szostkiewicz (10.4) | D19: Jarrett (8.9) | E19: 19.3 | F19: 0.124 | G19: =F19*G$2 -> 781.2 | H19: 175 | I19: Jarrett
A20: 16 | B20: Team Beat LA | C20: Cloepfil (12.3) | D20: McCormick (8.0) | E20: 20.3 | F20: 0.111 | G20: =F20*G$2 -> 699.3 | H20: 200 | I20: Jon
A21: 17 | B21: Team Island Time | C21: Mason (13.1) | D21: Bolosan (9.0) | E21: 22.1 | F21: 0.099 | G21: =F21*G$2 -> 623.7 | H21: 200 | I21: Bolosan
A22: 18 | B22: Team Sand | C22: Restivo (12.5) | D22: Wilson (13.0) | E22: 25.5 | F22: 0.092 | G22: =F22*G$2 -> 579.6 | H22: 250 | I22: Jon
A23: 19 | B23: Team Docks To Docs | C23: Caplan (17.8) | D23: Fellows (10.3) | E23: 28.1 | F23: 0.083 | G23: =F23*G$2 -> 522.9 | H23: 250 | I23: Jarrett
A24: 20 | B24: Team 20 | C24: Ackley (13.9) | D24: Oliver (18.1) | E24: 32 | F24: 0.083 | G24: =F24*G$2 -> 522.9 | H24: 225 | I24: DeLaveaga
A26: Totals | H26: =SUM(H5:H24) -> 6300
H27: 🏆 Day 1 Calcutta Scoreboard
A28: Payout Structure | B28: Premium (30%+) | C28: Solid (20-30%) | D28: Mid (10-20%) | E28: Long Shot (<10%) | H28: Team | I28: Flight | J28: Player 1 | K28: Player 2 | L28: Day 1 Score | M28: Rank
A29: Actual Pot: | B29: =H26 -> 6300 | H29: Pink Lady | I29: Tiger 🐯 | J29: Weiss (1.3) | K29: Marino (5.9) | L29: 64 | M29: T1
A30: Instructions: | H30: Team Sticks | I30: Tiger 🐯 | J30: Feutz (-1.0) | K30: Adams (-5.4) | L30: 64 | M30: T1
A31: Place | B31: Payout % | C31: Payout $ | H31: Team Timex | I31: Tiger 🐯 | J31: Vrolyks (5.7) | K31: Rucci (11.8) | L31: 64 | M31: T1
A32: 1st | B32: 0.5 | C32: =B32*$B$29 -> 3150 | H32: Team Winning | I32: Tiger 🐯 | J32: Royce (13.2) | K32: Deuker (2.6) | L32: 65 | M32: T4
A33: 2nd | B33: 0.25 | C33: =B33*$B$29 -> 1575 | H33: Papa Becko And The Bomber | I33: Rory 🦁 | J33: Becko (12.0) | K33: Lucas (9.9) | L33: 65 | M33: T4
A34: 3rd | B34: 0.15 | C34: =B34*$B$29 -> 945 | H34: Team Down The Middle | I34: Tiger 🐯 | J34: Mattson (2.3) | K34: Pullen (1.1) | L34: 66 | M34: 6
A35: 4th | B35: 0.1 | C35: =B35*$B$29 -> 630 | H35: Team DeLaFunk | I35: Tiger 🐯 | J35: Funk (4.9) | K35: Laveaga (0.2) | L35: 67 | M35: T7
H36: Team Beard | I36: Tiger 🐯 | J36: Becko (4.5) | K36: Wasmund (6.0) | L36: 67 | M36: T7
H37: Patty Ice And The Scrabble Rack | I37: Rory 🦁 | J37: Szostkiewicz (10.4) | K37: Jarrett (8.9) | L37: 68 | M37: T9
H38: Team Island Time | I38: Rory 🦁 | J38: Mason (13.1) | K38: Bolosan (9.0) | L38: 68 | M38: T9
H39: Team Foot Wedge | I39: Tiger 🐯 | J39: Muller (6.9) | K39: Eisenbarth (5.6) | L39: 69 | M39: T11
H40: Team Vanilla Slice | I40: Tiger 🐯 | J40: Jerome (9.5) | K40: Ingram (6.8) | L40: 69 | M40: T11
H41: Team Index | I41: Rory 🦁 | J41: Barber (17.0) | K41: Hill (19.6) | L41: 69 | M41: T11
...

Sheet Tiger Flight
A1: 🐯 Tiger Flight — Pick a Pro Shamble Scramble
A2: 2026 Master's Invitational at Sterling Grove CC
A3: Format: Day 1 Shamble (75% HCP, 6 drives/player) + Day 2 Best Ball (90% HCP) | Scoring: 2-Man Net Team Score + Pro Rd 3 + Rd 4 Scores
A5: Team | B5: Player 1 | C5: Player 2 | D5: Team HCP | E5: Pro Player A | F5: Pro Player B | G5: Day 1 Score (Shamble) | H5: Day 2 Net (Best Ball) | I5: Pro Rd 3A Score | J5: Pro Rd 3B Score | K5: Pro Rd 4A Score | L5: Pro Rd 4B Score | M5: Total Score | N5: Rank | O5: total team score
A6: Team DeLaFunk | B6: Funk (4.9) | C6: Laveaga (0.2) | D6: 5.1 | E6: Cameron Young | F6: Russell Henley | G6: 67 | H6: 64 | I6: =IFERROR(VLOOKUP(E6,'Pro Scores'!$A:$C,2,FALSE),"") -> 65 | J6: =IFERROR(VLOOKUP(F6,'Pro Scores'!$A:$C,2,FALSE),"") -> 66 | K6: =IFERROR(IF('Pro Scores'!C2="","",VLOOKUP(E6,'Pro Scores'!$A:$C,3,FALSE)),"") -> 73 | L6: =IFERROR(IF(VLOOKUP(F6,'Pro Scores'!$A:$C,3,FALSE)="","",VLOOKUP(F6,'Pro Scores'!$A:$C,3,FALSE)),"") -> 68 | M6: =SUM(G6:L6) -> 403 | N6: =IF(M6="","",RANK(M6,$M$6:$M$15,1)) -> 1 | O6: =G6+H6 -> 131
A7: Team Sticks | B7: Feutz (-1.0) | C7: Adams (-5.4) | D7: -6.4 | E7: Scottie Scheffler | F7: John Rahm | G7: 64 | H7: 66 | I7: =IFERROR(VLOOKUP(E7,'Pro Scores'!$A:$C,2,FALSE),"") -> 65 | J7: =IFERROR(VLOOKUP(F7,'Pro Scores'!$A:$C,2,FALSE),"") -> 73 | K7: =IFERROR(IF(VLOOKUP(E7,'Pro Scores'!$A:$C,3,FALSE)="","",VLOOKUP(E7,'Pro Scores'!$A:$C,3,FALSE)),"") -> 68 | L7: =IFERROR(IF(VLOOKUP(F7,'Pro Scores'!$A:$C,3,FALSE)="","",VLOOKUP(F7,'Pro Scores'!$A:$C,3,FALSE)),"") -> 68 | M7: =SUM(G7:L7) -> 404 | N7: =IF(M7="","",RANK(M7,$M$6:$M$15,1)) -> 2 | O7: =G7+H7 -> 130
A8: Team Down The Middle | B8: Mattson (2.3) | C8: Pullen (1.1) | D8: 3.4 | E8: Xander Schauffele | F8: Jordan Spieth | G8: 66 | H8: 69 | I8: =IFERROR(VLOOKUP(E8,'Pro Scores'!$A:$C,2,FALSE),"") -> 70 | J8: =IFERROR(VLOOKUP(F8,'Pro Scores'!$A:$C,2,FALSE),"") -> 70 | K8: =IFERROR(IF(VLOOKUP(E8,'Pro Scores'!$A:$C,3,FALSE)="","",VLOOKUP(E8,'Pro Scores'!$A:$C,3,FALSE)),"") -> 68 | L8: =IFERROR(IF(VLOOKUP(F8,'Pro Scores'!$A:$C,3,FALSE)="","",VLOOKUP(F8,'Pro Scores'!$A:$C,3,FALSE)),"") -> 68 | M8: =SUM(G8:L8) -> 411 | N8: =IF(M8="","",RANK(M8,$M$6:$M$15,1)) -> 3 | O8: =G8+H8 -> 135
A9: Team Winning | B9: Royce (13.2) | C9: Deuker (2.6) | D9: 15.8 | E9: Justin Rose | F9: John Rahm | G9: 65 | H9: 69 | I9: =IFERROR(VLOOKUP(E9,'Pro Scores'!$A:$C,2,FALSE),"") -> 69 | J9: =IFERROR(VLOOKUP(F9,'Pro Scores'!$A:$C,2,FALSE),"") -> 73 | K9: =IFERROR(IF(VLOOKUP(E9,'Pro Scores'!$A:$C,3,FALSE)="","",VLOOKUP(E9,'Pro Scores'!$A:$C,3,FALSE)),"") -> 70 | L9: =IFERROR(IF(VLOOKUP(F9,'Pro Scores'!$A:$C,3,FALSE)="","",VLOOKUP(F9,'Pro Scores'!$A:$C,3,FALSE)),"") -> 68 | M9: =SUM(G9:L9) -> 414 | N9: =IF(M9="","",RANK(M9,$M$6:$M$15,1)) -> 4 | O9: =G9+H9 -> 134
A10: Team Foot Wedge | B10: Muller (6.9) | C10: Eisenbarth (5.6) | D10: 12.5 | E10: Scottie Scheffler | F10: John Rahm | G10: 69 | H10: 73 | I10: =IFERROR(VLOOKUP(E10,'Pro Scores'!$A:$C,2,FALSE),"") -> 65 | J10: =IFERROR(VLOOKUP(F10,'Pro Scores'!$A:$C,2,FALSE),"") -> 73 | K10: =IFERROR(IF(VLOOKUP(E10,'Pro Scores'!$A:$C,3,FALSE)="","",VLOOKUP(E10,'Pro Scores'!$A:$C,3,FALSE)),"") -> 68 | L10: =IFERROR(IF(VLOOKUP(F10,'Pro Scores'!$A:$C,3,FALSE)="","",VLOOKUP(F10,'Pro Scores'!$A:$C,3,FALSE)),"") -> 68 | M10: =SUM(G10:L10) -> 416 | N10: =IF(M10="","",RANK(M10,$M$6:$M$15,1)) -> 5 | O10: =G10+H10 -> 142
A11: Team Vanilla Slice | B11: Jerome (9.5) | C11: Ingram (6.8) | D11: 16.3 | E11: Patrick Reed | F11: Patrick Cantlay | G11: 69 | H11: 66 | I11: =IFERROR(VLOOKUP(E11,'Pro Scores'!$A:$C,2,FALSE),"") -> 72 | J11: =IFERROR(VLOOKUP(F11,'Pro Scores'!$A:$C,2,FALSE),"") -> 66 | K11: =IFERROR(IF(VLOOKUP(E11,'Pro Scores'!$A:$C,3,FALSE)="","",VLOOKUP(E11,'Pro Scores'!$A:$C,3,FALSE)),"") -> 73 | L11: =IFERROR(IF(VLOOKUP(F11,'Pro Scores'!$A:$C,3,FALSE)="","",VLOOKUP(F11,'Pro Scores'!$A:$C,3,FALSE)),"") -> 73 | M11: =SUM(G11:L11) -> 419 | N11: =IF(M11="","",RANK(M11,$M$6:$M$15,1)) -> 6 | O11: =G11+H11 -> 135
A12: Pink Lady | B12: Weiss (1.3) | C12: Marino (5.9) | D12: 7.2 | E12: Patrick Reed | F12: Patrick Cantlay | G12: 64 | H12: 72 | I12: =IFERROR(VLOOKUP(E12,'Pro Scores'!$A:$C,2,FALSE),"") -> 72 | J12: =IFERROR(VLOOKUP(F12,'Pro Scores'!$A:$C,2,FALSE),"") -> 66 | K12: =IFERROR(IF(VLOOKUP(E12,'Pro Scores'!$A:$C,3,FALSE)="","",VLOOKUP(E12,'Pro Scores'!$A:$C,3,FALSE)),"") -> 73 | L12: =IFERROR(IF(VLOOKUP(F12,'Pro Scores'!$A:$C,3,FALSE)="","",VLOOKUP(F12,'Pro Scores'!$A:$C,3,FALSE)),"") -> 73 | M12: =SUM(G12:L12) -> 420 | N12: =IF(M12="","",RANK(M12,$M$6:$M$15,1)) -> 7 | O12: =G12+H12 -> 136
A13: Team Beard | B13: Becko (4.5) | C13: Wasmund (6.0) | D13: 10.5 | E13: Patrick Reed | F13: Patrick Cantlay | G13: 67 | H13: 69 | I13: =IFERROR(VLOOKUP(E13,'Pro Scores'!$A:$C,2,FALSE),"") -> 72 | J13: =IFERROR(VLOOKUP(F13,'Pro Scores'!$A:$C,2,FALSE),"") -> 66 | K13: =IFERROR(IF(VLOOKUP(E13,'Pro Scores'!$A:$C,3,FALSE)="","",VLOOKUP(E13,'Pro Scores'!$A:$C,3,FALSE)),"") -> 73 | L13: =IFERROR(IF(VLOOKUP(F13,'Pro Scores'!$A:$C,3,FALSE)="","",VLOOKUP(F13,'Pro Scores'!$A:$C,3,FALSE)),"") -> 73 | M13: =SUM(G13:L13) -> 420 | N13: =IF(M13="","",RANK(M13,$M$6:$M$15,1)) -> 7 | O13: =G13+H13 -> 136
A14: Team Timex | B14: Vrolyks (5.7) | C14: Rucci (11.8) | D14: 17.5 | E14: Rory McIlroy | F14: John Rahm | G14: 64 | H14: 73 | I14: =IFERROR(VLOOKUP(E14,'Pro Scores'!$A:$C,2,FALSE),"") -> 73 | J14: =IFERROR(VLOOKUP(F14,'Pro Scores'!$A:$C,2,FALSE),"") -> 73 | K14: =IFERROR(IF(VLOOKUP(E14,'Pro Scores'!$A:$C,3,FALSE)="","",VLOOKUP(E14,'Pro Scores'!$A:$C,3,FALSE)),"") -> 71 | L14: =IFERROR(IF(VLOOKUP(F14,'Pro Scores'!$A:$C,3,FALSE)="","",VLOOKUP(F14,'Pro Scores'!$A:$C,3,FALSE)),"") -> 68 | M14: =SUM(G14:L14) -> 422 | N14: =IF(M14="","",RANK(M14,$M$6:$M$15,1)) -> 9 | O14: =G14+H14 -> 137
A15: Team Low Expectations | B15: Falagrady (6.7) | C15: Benga (5.3) | D15: 12 | E15: Rory McIlroy | F15: John Rahm | G15: 70 | H15: 67 | I15: =IFERROR(VLOOKUP(E15,'Pro Scores'!$A:$C,2,FALSE),"") -> 73 | J15: =IFERROR(VLOOKUP(F15,'Pro Scores'!$A:$C,2,FALSE),"") -> 73 | K15: =IFERROR(IF(VLOOKUP(E15,'Pro Scores'!$A:$C,3,FALSE)="","",VLOOKUP(E15,'Pro Scores'!$A:$C,3,FALSE)),"") -> 71 | L15: =IFERROR(IF(VLOOKUP(F15,'Pro Scores'!$A:$C,3,FALSE)="","",VLOOKUP(F15,'Pro Scores'!$A:$C,3,FALSE)),"") -> 68 | M15: =SUM(G15:L15) -> 422 | N15: =IF(M15="","",RANK(M15,$M$6:$M$15,1)) -> 9 | O15: =G15+H15 -> 137
A17: Flight Payout
A18: Pot: | B18: 2000
A20: Place | B20: Payout $
A21: 1st | B21: 1200
A22: 2nd | B22: 500
A23: 3rd | B23: 300
A25: Scoring Rules
A26: • Day 1: 2-man shamble, 75% of team handicap (6 drives per player)
A27: • Day 2: 2-man best ball, 90% of team handicap
A28: • Total = Day 1 Net + Day 2 Net + Pro Player A Rd 3 + Pro Player B Rd 4
A29: • Lowest total score wins
A31: Tiebreakers
A32: 1. Team with the Masters winner as a selected pro
A33: 2. Lowest Net Day 2 back nine (Holes 10-18)
A34: 3. Lowest Net Day 2 final 6 holes (Holes 13-18)
A35: 4. Lowest Net Day 2 final 3 holes (Holes 16-18)
A36: 5. Prize money split

Sheet Rory Flight
A1: 🦁 Rory Flight — Pick a Pro Shamble Scramble
A2: 2026 Master's Invitational at Sterling Grove CC
A3: Format: Day 1 Shamble (75% HCP, 6 drives/player) + Day 2 Best Ball (90% HCP) | Scoring: 2-Man Net Team Score + Pro Rd 3 + Rd 4 Scores
A5: Team | B5: Player 1 | C5: Player 2 | D5: Team HCP | E5: Pro Player A | F5: Pro Player B | G5: Day 1 Score (Shamble) | H5: Day 2 Net (Best Ball) | I5: Pro Rd 3A Score | J5: Pro Rd 3B Score | K5: Pro Rd 4A Score | L5: Pro Rd 4B Score | M5: Total Score | N5: Rank | O5: total team score
A6: Papa Becko And The Bomber | B6: Becko (12.0) | C6: Lucas (9.9) | D6: 21.9 | E6: Scottie Scheffler | F6: Victor Hovland | G6: 65 | H6: 68 | I6: =IFERROR(VLOOKUP(E6,'Pro Scores'!$A:$C,2,FALSE),"") -> 65 | J6: =IFERROR(VLOOKUP(F6,'Pro Scores'!$A:$C,2,FALSE),"") -> 71 | K6: =IFERROR(IF(VLOOKUP(E6,'Pro Scores'!$A:$C,3,FALSE)="","",VLOOKUP(E6,'Pro Scores'!$A:$C,3,FALSE)),"") -> 68 | L6: =IFERROR(IF(VLOOKUP(F6,'Pro Scores'!$A:$C,3,FALSE)="","",VLOOKUP(F6,'Pro Scores'!$A:$C,3,FALSE)),"") -> 67 | M6: =SUM(G6:L6) -> 404 | N6: =IF(M6="","",RANK(M6,$M$6:$M$15,1)) -> 1 | O6: =G6+H6 -> 133
A7: Team Docks To Docs | B7: Caplan (17.8) | C7: Fellows (10.3) | D7: 28.1 | E7: Scottie Scheffler | F7: John Rahm | G7: 74 | H7: 66 | I7: =IFERROR(VLOOKUP(E7,'Pro Scores'!$A:$C,2,FALSE),"") -> 65 | J7: =IFERROR(VLOOKUP(F7,'Pro Scores'!$A:$C,2,FALSE),"") -> 73 | K7: =IFERROR(IF(VLOOKUP(E7,'Pro Scores'!$A:$C,3,FALSE)="","",VLOOKUP(E7,'Pro Scores'!$A:$C,3,FALSE)),"") -> 68 | L7: =IFERROR(IF(VLOOKUP(F7,'Pro Scores'!$A:$C,3,FALSE)="","",VLOOKUP(F7,'Pro Scores'!$A:$C,3,FALSE)),"") -> 68 | M7: =SUM(G7:L7) -> 414 | N7: =IF(M7="","",RANK(M7,$M$6:$M$15,1)) -> 2 | O7: =G7+H7 -> 140
A8: Team 5 O'Clock Somewhere | B8: Lewis (9.0) | C8: Schueppert (16.8) | D8: 25.8 | E8: Scottie Scheffler | F8: Victor Hovland | G8: 71 | H8: 72 | I8: =IFERROR(VLOOKUP(E8,'Pro Scores'!$A:$C,2,FALSE),"") -> 65 | J8: =IFERROR(VLOOKUP(F8,'Pro Scores'!$A:$C,2,FALSE),"") -> 71 | K8: =IFERROR(IF(VLOOKUP(E8,'Pro Scores'!$A:$C,3,FALSE)="","",VLOOKUP(E8,'Pro Scores'!$A:$C,3,FALSE)),"") -> 68 | L8: =IFERROR(IF(VLOOKUP(F8,'Pro Scores'!$A:$C,3,FALSE)="","",VLOOKUP(F8,'Pro Scores'!$A:$C,3,FALSE)),"") -> 67 | M8: =SUM(G8:L8) -> 414 | N8: =IF(M8="","",RANK(M8,$M$6:$M$15,1)) -> 2 | O8: =G8+H8 -> 143
A9: Patty Ice And The Scrabble Rack | B9: Szostkiewicz (10.4) | C9: Jarrett (8.9) | D9: 19.3 | E9: Justin Rose | F9: Jordan Spieth | G9: 68 | H9: 71 | I9: =IFERROR(VLOOKUP(E9,'Pro Scores'!$A:$C,2,FALSE),"") -> 69 | J9: =IFERROR(VLOOKUP(F9,'Pro Scores'!$A:$C,2,FALSE),"") -> 70 | K9: =IFERROR(IF(VLOOKUP(E9,'Pro Scores'!$A:$C,3,FALSE)="","",VLOOKUP(E9,'Pro Scores'!$A:$C,3,FALSE)),"") -> 70 | L9: =IFERROR(IF(VLOOKUP(F9,'Pro Scores'!$A:$C,3,FALSE)="","",VLOOKUP(F9,'Pro Scores'!$A:$C,3,FALSE)),"") -> 68 | M9: =SUM(G9:L9) -> 416 | N9: =IF(M9="","",RANK(M9,$M$6:$M$15,1)) -> 4 | O9: =G9+H9 -> 139
A10: Team Sand | B10: Restivo (12.5) | C10: Wilson (13.0) | D10: 25.5 | E10: Ludvig Åberg | F10: Victor Hovland | G10: 69 | H10: 69 | I10: =IFERROR(VLOOKUP(E10,'Pro Scores'!$A:$C,2,FALSE),"") -> 69 | J10: =IFERROR(VLOOKUP(F10,'Pro Scores'!$A:$C,2,FALSE),"") -> 71 | K10: =IFERROR(IF(VLOOKUP(E10,'Pro Scores'!$A:$C,3,FALSE)="","",VLOOKUP(E10,'Pro Scores'!$A:$C,3,FALSE)),"") -> 72 | L10: =IFERROR(IF(VLOOKUP(F10,'Pro Scores'!$A:$C,3,FALSE)="","",VLOOKUP(F10,'Pro Scores'!$A:$C,3,FALSE)),"") -> 67 | M10: =SUM(G10:L10) -> 417 | N10: =IF(M10="","",RANK(M10,$M$6:$M$15,1)) -> 5 | O10: =G10+H10 -> 138
A11: Team Index | B11: Barber (17.0) | C11: Hill (19.6) | D11: 36.6 | E11: Cameron Young | F11: Marco Penge | G11: 69 | H11: 67 | I11: =IFERROR(VLOOKUP(E11,'Pro Scores'!$A:$C,2,FALSE),"") -> 65 | J11: =IFERROR(VLOOKUP(F11,'Pro Scores'!$A:$C,2,FALSE),"") -> 71 | K11: =IFERROR(IF(VLOOKUP(E11,'Pro Scores'!$A:$C,3,FALSE)="","",VLOOKUP(E11,'Pro Scores'!$A:$C,3,FALSE)),"") -> 73 | L11: =IFERROR(IF(VLOOKUP(F11,'Pro Scores'!$A:$C,3,FALSE)="","",VLOOKUP(F11,'Pro Scores'!$A:$C,3,FALSE)),"") -> 78 | M11: =SUM(G11:L11) -> 423 | N11: =IF(M11="","",RANK(M11,$M$6:$M$15,1)) -> 6 | O11: =G11+H11 -> 136
A12: Team Rough Extractions | B12: Mueller (10.4) | C12: Bellows (7.5) | D12: 17.9 | E12: Wyndham Clark | F12: Patrick Cantlay | G12: 70 | H12: 71 | I12: =IFERROR(VLOOKUP(E12,'Pro Scores'!$A:$C,2,FALSE),"") -> 72 | J12: =IFERROR(VLOOKUP(F12,'Pro Scores'!$A:$C,2,FALSE),"") -> 66 | K12: =IFERROR(IF(VLOOKUP(E12,'Pro Scores'!$A:$C,3,FALSE)="","",VLOOKUP(E12,'Pro Scores'!$A:$C,3,FALSE)),"") -> 73 | L12: =IFERROR(IF(VLOOKUP(F12,'Pro Scores'!$A:$C,3,FALSE)="","",VLOOKUP(F12,'Pro Scores'!$A:$C,3,FALSE)),"") -> 73 | M12: =SUM(G12:L12) -> 425 | N12: =IF(M12="","",RANK(M12,$M$6:$M$15,1)) -> 7 | O12: =G12+H12 -> 141
A13: Team Beat LA | B13: Cloepfil (12.3) | C13: McCormick (8.0) | D13: 20.3 | E13: Patrick Reed | F13: Justin Thomas | G13: 70 | H13: 67 | I13: =IFERROR(VLOOKUP(E13,'Pro Scores'!$A:$C,2,FALSE),"") -> 72 | J13: =IFERROR(VLOOKUP(F13,'Pro Scores'!$A:$C,2,FALSE),"") -> 71 | K13: =IFERROR(IF(VLOOKUP(E13,'Pro Scores'!$A:$C,3,FALSE)="","",VLOOKUP(E13,'Pro Scores'!$A:$C,3,FALSE)),"") -> 73 | L13: =IFERROR(IF(VLOOKUP(F13,'Pro Scores'!$A:$C,3,FALSE)="","",VLOOKUP(F13,'Pro Scores'!$A:$C,3,FALSE)),"") -> 73 | M13: =SUM(G13:L13) -> 426 | N13: =IF(M13="","",RANK(M13,$M$6:$M$15,1)) -> 8 | O13: =G13+H13 -> 137
A14: Team Island Time | B14: Mason (13.1) | C14: Bolosan (9.0) | D14: 22.1 | E14: Rory McIlroy | F14: Sungjae Im | G14: 68 | H14: 70 | I14: =IFERROR(VLOOKUP(E14,'Pro Scores'!$A:$C,2,FALSE),"") -> 73 | J14: =IFERROR(VLOOKUP(F14,'Pro Scores'!$A:$C,2,FALSE),"") -> 69 | K14: =IFERROR(IF(VLOOKUP(E14,'Pro Scores'!$A:$C,3,FALSE)="","",VLOOKUP(E14,'Pro Scores'!$A:$C,3,FALSE)),"") -> 71 | L14: =IFERROR(IF(VLOOKUP(F14,'Pro Scores'!$A:$C,3,FALSE)="","",VLOOKUP(F14,'Pro Scores'!$A:$C,3,FALSE)),"") -> 77 | M14: =SUM(G14:L14) -> 428 | N14: =IF(M14="","",RANK(M14,$M$6:$M$15,1)) -> 9 | O14: =G14+H14 -> 138
A15: Team 20 | B15: Ackley (13.9) | C15: Oliver (18.1) | D15: 32 | E15: Rory McIlroy | F15: Marco Penge | G15: 69 | H15: 72 | I15: =IFERROR(VLOOKUP(E15,'Pro Scores'!$A:$C,2,FALSE),"") -> 73 | J15: =IFERROR(VLOOKUP(F15,'Pro Scores'!$A:$C,2,FALSE),"") -> 71 | K15: =IFERROR(IF(VLOOKUP(E15,'Pro Scores'!$A:$C,3,FALSE)="","",VLOOKUP(E15,'Pro Scores'!$A:$C,3,FALSE)),"") -> 71 | L15: =IFERROR(IF(VLOOKUP(F15,'Pro Scores'!$A:$C,3,FALSE)="","",VLOOKUP(F15,'Pro Scores'!$A:$C,3,FALSE)),"") -> 78 | M15: =SUM(G15:L15) -> 434 | N15: =IF(M15="","",RANK(M15,$M$6:$M$15,1)) -> 10 | O15: =G15+H15 -> 141
A17: Flight Payout
A18: Pot: | B18: 2000
A20: Place | B20: Payout $
A21: 1st | B21: 1200
A22: 2nd | B22: 500
A23: 3rd | B23: 300
A25: Scoring Rules
A26: • Day 1: 2-man shamble, 75% of team handicap (6 drives per player)
A27: • Day 2: 2-man best ball, 90% of team handicap
A28: • Total = Day 1 Net + Day 2 Net + Pro Player A Rd 3 + Pro Player B Rd 4
A29: • Lowest total score wins
A31: Tiebreakers
A32: 1. Team with the Masters winner as a selected pro
A33: 2. Lowest Net Day 2 back nine (Holes 10-18)
A34: 3. Lowest Net Day 2 final 6 holes (Holes 13-18)
A35: 4. Lowest Net Day 2 final 3 holes (Holes 16-18)
A36: 5. Prize money split

Sheet Pro Scores
A1: Pro Player | B1: Saturday (Rd 3) Total Score | C1: Sunday (Rd 4) Total Score | D1: Total Score
A2: Cameron Young | B2: 65 | C2: 73 | D2: =IF(AND(B2="",C2=""),"",IF(B2="",C2,IF(C2="",B2,B2+C2))) -> 138
A3: John Rahm | B3: 73 | C3: 68 | D3: =IF(AND(B3="",C3=""),"",IF(B3="",C3,IF(C3="",B3,B3+C3))) -> 141
A4: Jordan Spieth | B4: 70 | C4: 68 | D4: =IF(AND(B4="",C4=""),"",IF(B4="",C4,IF(C4="",B4,B4+C4))) -> 138
A5: Justin Rose | B5: 69 | C5: 70 | D5: =IF(AND(B5="",C5=""),"",IF(B5="",C5,IF(C5="",B5,B5+C5))) -> 139
A6: Justin Thomas | B6: 71 | C6: 73 | D6: =IF(AND(B6="",C6=""),"",IF(B6="",C6,IF(C6="",B6,B6+C6))) -> 144
A7: Ludvig Åberg | B7: 69 | C7: 72 | D7: =IF(AND(B7="",C7=""),"",IF(B7="",C7,IF(C7="",B7,B7+C7))) -> 141
A8: Marco Penge | B8: 71 | C8: 78 | D8: =IF(AND(B8="",C8=""),"",IF(B8="",C8,IF(C8="",B8,B8+C8))) -> 149
A9: Patrick Cantlay | B9: 66 | C9: 73 | D9: =IF(AND(B9="",C9=""),"",IF(B9="",C9,IF(C9="",B9,B9+C9))) -> 139
A10: Patrick Reed | B10: 72 | C10: 73 | D10: =IF(AND(B10="",C10=""),"",IF(B10="",C10,IF(C10="",B10,B10+C10))) -> 145
A11: Rory McIlroy | B11: 73 | C11: 71 | D11: =IF(AND(B11="",C11=""),"",IF(B11="",C11,IF(C11="",B11,B11+C11))) -> 144
A12: Russell Henley | B12: 66 | C12: 68 | D12: =IF(AND(B12="",C12=""),"",IF(B12="",C12,IF(C12="",B12,B12+C12))) -> 134
A13: Scottie Scheffler | B13: 65 | C13: 68 | D13: =IF(AND(B13="",C13=""),"",IF(B13="",C13,IF(C13="",B13,B13+C13))) -> 133
... A17: Xander Schauffele | B17: 70 | C17: 68 | D17: =IF(AND(B17="",C17=""),"",IF(B17="",C17,IF(C17="",B17,B17+C17))) -> 138

Sheet Calcutta Scoreboard
A1: 🏆 Sterling Grove Masters — Calcutta Scoreboard
A2: 2026 Masters Invitational at Sterling Grove CC
A3: Pot Size: | B3: 6300 | C3: 1st Place (50%): | D3: =B3*0.5 -> 3150 | E3: 2nd Place (25%): | F3: =B3*0.25 -> 1575 | G3: 3rd Place (15%): | H3: =B3*0.15 -> 945 | I3: =B3*0.1 -> 630
A5: Rank | B5: Team | C5: Flight | D5: Player 1 | E5: Player 2 | F5: Day 1 Score | G5: Day 2 Score | H5: Total Score | I5: Payout | J5: Owner
A6: =IF(H6="","",RANK(H6,H$6:H$25,1)) -> 7 | B6: Pink Lady | C6: Tiger 🐯 | D6: Weiss (1.3) | E6: Marino (5.9) | F6: 64 | G6: 72 | H6: =IF(AND(F6<>"",G6<>""),F6+G6,IF(F6<>"",F6,"")) -> 136 | J6: Jon
A7: =IF(H7="","",RANK(H7,H$6:H$25,1)) -> 1 | B7: Team Sticks | C7: Tiger 🐯 | D7: Feutz (-1.0) | E7: Adams (-5.4) | F7: 64 | G7: 66 | H7: =IF(AND(F7<>"",G7<>""),F7+G7,IF(F7<>"",F7,"")) -> 130 | J7: Feutz
A8: =IF(H8="","",RANK(H8,H$6:H$25,1)) -> 10 | B8: Team Timex | C8: Tiger 🐯 | D8: Vrolyks (5.7) | E8: Rucci (11.8) | F8: 64 | G8: 73 | H8: =IF(AND(F8<>"",G8<>""),F8+G8,IF(F8<>"",F8,"")) -> 137 | J8: Jon
A9: =IF(H9="","",RANK(H9,H$6:H$25,1)) -> 4 | B9: Team Winning | C9: Tiger 🐯 | D9: Royce (13.2) | E9: Deuker (2.6) | F9: 65 | G9: 69 | H9: =IF(AND(F9<>"",G9<>""),F9+G9,IF(F9<>"",F9,"")) -> 134 | J9: DeLaveaga
A10: =IF(H10="","",RANK(H10,H$6:H$25,1)) -> 3 | B10: Papa Becko And The Bomber | C10: Rory 🦁 | D10: Becko (12.0) | E10: Lucas (9.9) | F10: 65 | G10: 68 | H10: =IF(AND(F10<>"",G10<>""),F10+G10,IF(F10<>"",F10,"")) -> 133 | J10: Bellows
A11: =IF(H11="","",RANK(H11,H$6:H$25,1)) -> 5 | B11: Team Down The Middle | C11: Tiger 🐯 | D11: Mattson (2.3) | E11: Pullen (1.1) | F11: 66 | G11: 69 | H11: =IF(AND(F11<>"",G11<>""),F11+G11,IF(F11<>"",F11,"")) -> 135 | J11: Restivo
A12: =IF(H12="","",RANK(H12,H$6:H$25,1)) -> 2 | B12: Team DeLaFunk | C12: Tiger 🐯 | D12: Funk (4.9) | E12: Laveaga (0.2) | F12: 67 | G12: 64 | H12: =IF(AND(F12<>"",G12<>""),F12+G12,IF(F12<>"",F12,"")) -> 131 | J12: Royce
A13: =IF(H13="","",RANK(H13,H$6:H$25,1)) -> 7 | B13: Team Beard | C13: Tiger 🐯 | D13: Becko (4.5) | E13: Wasmund (6.0) | F13: 67 | G13: 69 | H13: =IF(AND(F13<>"",G13<>""),F13+G13,IF(F13<>"",F13,"")) -> 136 | J13: Dusty
A14: =IF(H14="","",RANK(H14,H$6:H$25,1)) -> 15 | B14: Patty Ice And The Scrabble Rack | C14: Rory 🦁 | D14: Szostkiewicz (10.4) | E14: Jarrett (8.9) | F14: 68 | G14: 71 | H14: =IF(AND(F14<>"",G14<>""),F14+G14,IF(F14<>"",F14,"")) -> 139 | J14: Jarrett
A15: =IF(H15="","",RANK(H15,H$6:H$25,1)) -> 13 | B15: Team Island Time | C15: Rory 🦁 | D15: Mason (13.1) | E15: Bolosan (9.0) | F15: 68 | G15: 70 | H15: =IF(AND(F15<>"",G15<>""),F15+G15,IF(F15<>"",F15,"")) -> 138 | J15: Bolosan
A16: =IF(H16="","",RANK(H16,H$6:H$25,1)) -> 19 | B16: Team Foot Wedge | C16: Tiger 🐯 | D16: Muller (6.9) | E16: Eisenbarth (5.6) | F16: 69 | G16: 73 | H16: =IF(AND(F16<>"",G16<>""),F16+G16,IF(F16<>"",F16,"")) -> 142 | J16: Jon
A17: =IF(H17="","",RANK(H17,H$6:H$25,1)) -> 5 | B17: Team Vanilla Slice | C17: Tiger 🐯 | D17: Jerome (9.5) | E17: Ingram (6.8) | F17: 69 | G17: 66 | H17: =IF(AND(F17<>"",G17<>""),F17+G17,IF(F17<>"",F17,"")) -> 135 | J17: Ingram
... A25: =IF(H25="","",RANK(H25,H$6:H$25,1)) -> 16 | B25: Team Docks To Docs | C25: Rory 🦁 | D25: Caplan (17.8) | E25: Fellows (10.3) | F25: 74 | G25: 66 | H25: =IF(AND(F25<>"",G25<>""),F25+G25,IF(F25<>"",F25,"")) -> 140 | J25: Jarrett
A27: 🔗 TIEBREAKER RULES
A28: 1️⃣ | B28: Lowest Back 9 Score (Holes 10–18) on Day 2 | C28: → Enter in Tiebreaker Notes column if needed
A29: 2️⃣ | B29: Lowest Score Holes 13–18 on Day 2 | C29: → If still tied after Tiebreaker 1
A30: 3️⃣ | B30: Lowest Score Holes 16–18 on Day 2 | C30: → If still tied after Tiebreaker 2
A31: 4️⃣ | B31: Prize Money Split Equally | C31: → If all tiebreakers still tied, split the combined payout evenly
A33: 💰 PAYOUT SUMMARY
A34: Place | B34: Payout % | C34: Payout $ | D34: Leader (Auto)
A35: 1st 🥇 | B35: 0.5 | C35: =$B$3*0.5 -> 3150 | D35: =IFERROR(INDEX(B$6:B$25,MATCH(1,A$6:A$25,0)),"TBD") -> Team Sticks
A36: 2nd 🥈 | B36: 0.25 | C36: =$B$3*0.25 -> 1575 | D36: =IFERROR(INDEX(B$6:B$25,MATCH(2,A$6:A$25,0)),"TBD") -> Team DeLaFunk
A37: 3rd 🥉 | B37: 0.15 | C37: =$B$3*0.15 -> 945 | D37: =IFERROR(INDEX(B$6:B$25,MATCH(3,A$6:A$25,0)),"TBD") -> Papa Becko And The Bomber
A38: 4th | B38: 0.1 | C38: =$B$3*0.1 -> 630 | D38: =IFERROR(INDEX(B$6:B$25,MATCH(4,A$6:A$25,0)),"TBD") -> Team Winning
A40: ⚠️ Tied Payout Note: | B40: When teams are tied in rank, payout = combined prize for tied places ÷ number of tied teams. Enter split amount manually in Payout column (J) after applying tiebreakers.
A42: 🏆 Final Payout Breakdown
A43: Place | B43: Team | C43: Owner | D43: Payout | E43: Notes
